Traceback (most recent call last):
  File "/Users/christoszacharopoulos/anaconda3/envs/mlflow-ba66c90db42a008eeacbeeadf1038be29b5db81a/lib/python3.8/site-packages/urllib3/connectionpool.py", line 703, in urlopen
    httplib_response = self._make_request(
  File "/Users/christoszacharopoulos/anaconda3/envs/mlflow-ba66c90db42a008eeacbeeadf1038be29b5db81a/lib/python3.8/site-packages/urllib3/connectionpool.py", line 386, in _make_request
    self._validate_conn(conn)
  File "/Users/christoszacharopoulos/anaconda3/envs/mlflow-ba66c90db42a008eeacbeeadf1038be29b5db81a/lib/python3.8/site-packages/urllib3/connectionpool.py", line 1042, in _validate_conn
    conn.connect()
  File "/Users/christoszacharopoulos/anaconda3/envs/mlflow-ba66c90db42a008eeacbeeadf1038be29b5db81a/lib/python3.8/site-packages/urllib3/connection.py", line 414, in connect
    self.sock = ssl_wrap_socket(
  File "/Users/christoszacharopoulos/anaconda3/envs/mlflow-ba66c90db42a008eeacbeeadf1038be29b5db81a/lib/python3.8/site-packages/urllib3/util/ssl_.py", line 449, in ssl_wrap_socket
    ssl_sock = _ssl_wrap_socket_impl(
  File "/Users/christoszacharopoulos/anaconda3/envs/mlflow-ba66c90db42a008eeacbeeadf1038be29b5db81a/lib/python3.8/site-packages/urllib3/util/ssl_.py", line 493, in _ssl_wrap_socket_impl
    return ssl_context.wrap_socket(sock, server_hostname=server_hostname)
  File "/Users/christoszacharopoulos/anaconda3/envs/mlflow-ba66c90db42a008eeacbeeadf1038be29b5db81a/lib/python3.8/ssl.py", line 500, in wrap_socket
    return self.sslsocket_class._create(
  File "/Users/christoszacharopoulos/anaconda3/envs/mlflow-ba66c90db42a008eeacbeeadf1038be29b5db81a/lib/python3.8/ssl.py", line 1019, in _create
    self.getpeername()
OSError: [Errno 22] Invalid argument
During handling of the above exception, another exception occurred:
Traceback (most recent call last):
  File "/Users/christoszacharopoulos/anaconda3/envs/mlflow-ba66c90db42a008eeacbeeadf1038be29b5db81a/lib/python3.8/site-packages/requests/adapters.py", line 489, in send
    resp = conn.urlopen(
  File "/Users/christoszacharopoulos/anaconda3/envs/mlflow-ba66c90db42a008eeacbeeadf1038be29b5db81a/lib/python3.8/site-packages/urllib3/connectionpool.py", line 787, in urlopen
    retries = retries.increment(
  File "/Users/christoszacharopoulos/anaconda3/envs/mlflow-ba66c90db42a008eeacbeeadf1038be29b5db81a/lib/python3.8/site-packages/urllib3/util/retry.py", line 550, in increment
    raise six.reraise(type(error), error, _stacktrace)
  File "/Users/christoszacharopoulos/anaconda3/envs/mlflow-ba66c90db42a008eeacbeeadf1038be29b5db81a/lib/python3.8/site-packages/urllib3/packages/six.py", line 769, in reraise
    raise value.with_traceback(tb)
  File "/Users/christoszacharopoulos/anaconda3/envs/mlflow-ba66c90db42a008eeacbeeadf1038be29b5db81a/lib/python3.8/site-packages/urllib3/connectionpool.py", line 703, in urlopen
    httplib_response = self._make_request(
  File "/Users/christoszacharopoulos/anaconda3/envs/mlflow-ba66c90db42a008eeacbeeadf1038be29b5db81a/lib/python3.8/site-packages/urllib3/connectionpool.py", line 386, in _make_request
    self._validate_conn(conn)
  File "/Users/christoszacharopoulos/anaconda3/envs/mlflow-ba66c90db42a008eeacbeeadf1038be29b5db81a/lib/python3.8/site-packages/urllib3/connectionpool.py", line 1042, in _validate_conn
    conn.connect()
  File "/Users/christoszacharopoulos/anaconda3/envs/mlflow-ba66c90db42a008eeacbeeadf1038be29b5db81a/lib/python3.8/site-packages/urllib3/connection.py", line 414, in connect
    self.sock = ssl_wrap_socket(
  File "/Users/christoszacharopoulos/anaconda3/envs/mlflow-ba66c90db42a008eeacbeeadf1038be29b5db81a/lib/python3.8/site-packages/urllib3/util/ssl_.py", line 449, in ssl_wrap_socket
    ssl_sock = _ssl_wrap_socket_impl(
  File "/Users/christoszacharopoulos/anaconda3/envs/mlflow-ba66c90db42a008eeacbeeadf1038be29b5db81a/lib/python3.8/site-packages/urllib3/util/ssl_.py", line 493, in _ssl_wrap_socket_impl
    return ssl_context.wrap_socket(sock, server_hostname=server_hostname)
  File "/Users/christoszacharopoulos/anaconda3/envs/mlflow-ba66c90db42a008eeacbeeadf1038be29b5db81a/lib/python3.8/ssl.py", line 500, in wrap_socket
    return self.sslsocket_class._create(
  File "/Users/christoszacharopoulos/anaconda3/envs/mlflow-ba66c90db42a008eeacbeeadf1038be29b5db81a/lib/python3.8/ssl.py", line 1019, in _create
    self.getpeername()
urllib3.exceptions.ProtocolError: ('Connection aborted.', OSError(22, 'Invalid argument'))
During handling of the above exception, another exception occurred:
Traceback (most recent call last):
  File "run.py", line 282, in <module>
    go(args)
  File "run.py", line 56, in go
    trainval_local_path = run.use_artifact(args.trainval_artifact).file()
  File "/Users/christoszacharopoulos/anaconda3/envs/mlflow-ba66c90db42a008eeacbeeadf1038be29b5db81a/lib/python3.8/site-packages/wandb/apis/public.py", line 4637, in file
    manifest = self._load_manifest()
  File "/Users/christoszacharopoulos/anaconda3/envs/mlflow-ba66c90db42a008eeacbeeadf1038be29b5db81a/lib/python3.8/site-packages/wandb/apis/public.py", line 4819, in _load_manifest
    with requests.get(index_file_url) as req:
  File "/Users/christoszacharopoulos/anaconda3/envs/mlflow-ba66c90db42a008eeacbeeadf1038be29b5db81a/lib/python3.8/site-packages/requests/api.py", line 73, in get
    return request("get", url, params=params, **kwargs)
  File "/Users/christoszacharopoulos/anaconda3/envs/mlflow-ba66c90db42a008eeacbeeadf1038be29b5db81a/lib/python3.8/site-packages/requests/api.py", line 59, in request
    return session.request(method=method, url=url, **kwargs)
  File "/Users/christoszacharopoulos/anaconda3/envs/mlflow-ba66c90db42a008eeacbeeadf1038be29b5db81a/lib/python3.8/site-packages/requests/sessions.py", line 587, in request
    resp = self.send(prep, **send_kwargs)
  File "/Users/christoszacharopoulos/anaconda3/envs/mlflow-ba66c90db42a008eeacbeeadf1038be29b5db81a/lib/python3.8/site-packages/requests/sessions.py", line 701, in send
    r = adapter.send(request, **kwargs)
  File "/Users/christoszacharopoulos/anaconda3/envs/mlflow-ba66c90db42a008eeacbeeadf1038be29b5db81a/lib/python3.8/site-packages/requests/adapters.py", line 547, in send
    raise ConnectionError(err, request=request)
requests.exceptions.ConnectionError: ('Connection aborted.', OSError(22, 'Invalid argument'))